Workbook

Sheet Start Here
A1: Debt Free Plan
A2: See your debt-free date and exactly what to pay each month
B4: YOUR SETTINGS
B5: Total you can pay toward debt each month | C5: 1200 | D5: Include all minimum payments plus any extra you can afford.
B6: Plan start month | C6: 46296 | D6: The first month you'll follow this plan.
B7: Payoff method | C7: Avalanche | D7: Avalanche = highest interest first (saves the most). Snowball = smallest balance first (fastest wins).
B10: HOW TO USE
B11: 1. List your debts on the My Debts tab: name, balance, interest rate (APR) and minimum payment.
B12: 2. Enter your monthly debt budget above (yellow cells = type here).
B13: 3. Open My Plan to see your debt-free date, total interest, and what to pay this month.
B14: 4. Pick Avalanche or Snowball above. My Plan compares both so you can see the difference.
B15: 5. Each month, pay the amounts shown. When one debt is paid off, its payment rolls to the next.
B16: 6. Update balances every few months so the plan stays accurate.
B17: Tip: in Google Sheets, open the file from Google Drive or use File > Import.
B19: Estimates assume fixed interest rates and on-time payments, with no new charges. Not financial advice.

Sheet My Plan
A1: My Plan
B2: ="Your "&LOWER('Start Here'!$C$7)&" plan · starting "&TEXT('Start Here'!$C$6,"mmmm yyyy") -> Your avalanche plan · starting October 2026
B3: =IF('Start Here'!$C$5<'My Debts'!$E$16,"⚠ Your monthly budget is less than your minimum payments ("&TEXT('My Debts'!$E$16,"$#,##0")&"). This plan assumes you still pay every minimum. Raise your budget on Start Here.","")
B5: DEBT-FREE DATE | D5: MONTHS TO GO | G5: TOTAL INTEREST | I5: TOTAL YOU'LL PAY
B6: =IF(IF('Start Here'!$C$7="Snowball",COUNTIF('Snowball Schedule'!$AG$7:$AG$366,">0.005")+1,COUNTIF('Avalanche Schedule'!$AG$7:$AG$366,">0.005")+1)>360,"30+ years",DATE(YEAR('Start Here'!$C$6),MONTH('Start Here'!$C$6)+IF('Start Here'!$C$7="Snowball",COUNTIF('Snowball Schedule'!$AG$7:$AG$366,">0.005")+1,COUNTIF('Avalanche Schedule'!$AG$7:$AG$366,">0.005")+1)-1,1)) -> 46692 | D6: =IF(IF('Start Here'!$C$7="Snowball",COUNTIF('Snowball Schedule'!$AG$7:$AG$366,">0.005")+1,COUNTIF('Avalanche Schedule'!$AG$7:$AG$366,">0.005")+1)>360,"30+",IF('Start Here'!$C$7="Snowball",COUNTIF('Snowball Schedule'!$AG$7:$AG$366,">0.005")+1,COUNTIF('Avalanche Schedule'!$AG$7:$AG$366,">0.005")+1)) -> 14 | G6: =IF('Start Here'!$C$7="Snowball",SUM('Snowball Schedule'!$AH$7:$AH$366),SUM('Avalanche Schedule'!$AH$7:$AH$366)) -> 847.68 | I6: ='My Debts'!$C$16+IF('Start Here'!$C$7="Snowball",SUM('Snowball Schedule'!$AH$7:$AH$366),SUM('Avalanche Schedule'!$AH$7:$AH$366)) -> 15697.68
B10: WHAT TO PAY THIS MONTH | D10: Month # | E10: 1 | G10: SNOWBALL vs AVALANCHE
B11: Debt | C11: Pay this month | D11: Balance after | E11: Order | H11: Snowball | I11: Avalanche | J11: Difference
B12: =IF('My Debts'!$B$6="","",'My Debts'!$B$6) -> Store card (example) | C12: =IF(B12="","",IF('Start Here'!$C$7="Snowball",INDEX('Snowball Schedule'!$B$7:$B$366,$E$10)-INDEX('Snowball Schedule'!$V$7:$V$366,$E$10),INDEX('Avalanche Schedule'!$B$7:$B$366,$E$10)-INDEX('Avalanche Schedule'!$V$7:$V$366,$E$10))) -> 805 | D12: =IF(B12="","",IF('Start Here'!$C$7="Snowball",INDEX('Snowball Schedule'!$V$7:$V$366,$E$10),INDEX('Avalanche Schedule'!$V$7:$V$366,$E$10))) -> 64.12 | E12: =IF(B12="","",IF('Start Here'!$C$7="Snowball",'My Debts'!$F$6,'My Debts'!$G$6)) -> 1 | G12: Debt-free in (months) | H12: =IF(COUNTIF('Snowball Schedule'!$AG$7:$AG$366,">0.005")+1>360,"30+ yrs",COUNTIF('Snowball Schedule'!$AG$7:$AG$366,">0.005")+1) -> 14 | I12: =IF(COUNTIF('Avalanche Schedule'!$AG$7:$AG$366,">0.005")+1>360,"30+ yrs",COUNTIF('Avalanche Schedule'!$AG$7:$AG$366,">0.005")+1) -> 14 | J12: =IFERROR(H12-I12,"-") -> 0
B13: =IF('My Debts'!$B$7="","",'My Debts'!$B$7) -> Visa (example) | C13: =IF(B13="","",IF('Start Here'!$C$7="Snowball",INDEX('Snowball Schedule'!$C$7:$C$366,$E$10)-INDEX('Snowball Schedule'!$W$7:$W$366,$E$10),INDEX('Avalanche Schedule'!$C$7:$C$366,$E$10)-INDEX('Avalanche Schedule'!$W$7:$W$366,$E$10))) -> 110 | D13: =IF(B13="","",IF('Start Here'!$C$7="Snowball",INDEX('Snowball Schedule'!$W$7:$W$366,$E$10),INDEX('Avalanche Schedule'!$W$7:$W$366,$E$10))) -> 4168.72 | E13: =IF(B13="","",IF('Start Here'!$C$7="Snowball",'My Debts'!$F$7,'My Debts'!$G$7)) -> 2 | G13: Total interest | H13: =SUM('Snowball Schedule'!$AH$7:$AH$366) -> 847.68 | I13: =SUM('Avalanche Schedule'!$AH$7:$AH$366) -> 847.68 | J13: =IFERROR(H13-I13,"-") -> 0
B14: =IF('My Debts'!$B$8="","",'My Debts'!$B$8) -> Car loan (example) | C14: =IF(B14="","",IF('Start Here'!$C$7="Snowball",INDEX('Snowball Schedule'!$D$7:$D$366,$E$10)-INDEX('Snowball Schedule'!$X$7:$X$366,$E$10),INDEX('Avalanche Schedule'!$D$7:$D$366,$E$10)-INDEX('Avalanche Schedule'!$X$7:$X$366,$E$10))) -> 285 | D14: =IF(B14="","",IF('Start Here'!$C$7="Snowball",INDEX('Snowball Schedule'!$X$7:$X$366,$E$10),INDEX('Avalanche Schedule'!$X$7:$X$366,$E$10))) -> 9571.35 | E14: =IF(B14="","",IF('Start Here'!$C$7="Snowball",'My Debts'!$F$8,'My Debts'!$G$8)) -> 3
B15: =IF('My Debts'!$B$9="","",'My Debts'!$B$9) | C15: =IF(B15="","",IF('Start Here'!$C$7="Snowball",INDEX('Snowball Schedule'!$E$7:$E$366,$E$10)-INDEX('Snowball Schedule'!$Y$7:$Y$366,$E$10),INDEX('Avalanche Schedule'!$E$7:$E$366,$E$10)-INDEX('Avalanche Schedule'!$Y$7:$Y$366,$E$10))) | D15: =IF(B15="","",IF('Start Here'!$C$7="Snowball",INDEX('Snowball Schedule'!$Y$7:$Y$366,$E$10),INDEX('Avalanche Schedule'!$Y$7:$Y$366,$E$10))) | E15: =IF(B15="","",IF('Start Here'!$C$7="Snowball",'My Debts'!$F$9,'My Debts'!$G$9)) | G15: =IF('My Debts'!$C$16=0,"",IF(J13>0.5,"Avalanche saves you "&TEXT(J13,"$#,##0")&" in interest.","Both methods cost about the same here, so Snowball's quick wins are a free bonus.")) -> Both methods cost about the same here, so Snowball's quick wins are a free bonus.
B16: =IF('My Debts'!$B$10="","",'My Debts'!$B$10) | C16: =IF(B16="","",IF('Start Here'!$C$7="Snowball",INDEX('Snowball Schedule'!$F$7:$F$366,$E$10)-INDEX('Snowball Schedule'!$Z$7:$Z$366,$E$10),INDEX('Avalanche Schedule'!$F$7:$F$366,$E$10)-INDEX('Avalanche Schedule'!$Z$7:$Z$366,$E$10))) | D16: =IF(B16="","",IF('Start Here'!$C$7="Snowball",INDEX('Snowball Schedule'!$Z$7:$Z$366,$E$10),INDEX('Avalanche Schedule'!$Z$7:$Z$366,$E$10))) | E16: =IF(B16="","",IF('Start Here'!$C$7="Snowball",'My Debts'!$F$10,'My Debts'!$G$10)) | G16: Snowball pays off small debts first for quick wins and motivation.
B17: =IF('My Debts'!$B$11="","",'My Debts'!$B$11) | C17: =IF(B17="","",IF('Start Here'!$C$7="Snowball",INDEX('Snowball Schedule'!$G$7:$G$366,$E$10)-INDEX('Snowball Schedule'!$AA$7:$AA$366,$E$10),INDEX('Avalanche Schedule'!$G$7:$G$366,$E$10)-INDEX('Avalanche Schedule'!$AA$7:$AA$366,$E$10))) | D17: =IF(B17="","",IF('Start Here'!$C$7="Snowball",INDEX('Snowball Schedule'!$AA$7:$AA$366,$E$10),INDEX('Avalanche Schedule'!$AA$7:$AA$366,$E$10))) | E17: =IF(B17="","",IF('Start Here'!$C$7="Snowball",'My Debts'!$F$11,'My Debts'!$G$11)) | G17: Avalanche targets the highest interest first and usually costs less.
B18: =IF('My Debts'!$B$12="","",'My Debts'!$B$12) | C18: =IF(B18="","",IF('Start Here'!$C$7="Snowball",INDEX('Snowball Schedule'!$H$7:$H$366,$E$10)-INDEX('Snowball Schedule'!$AB$7:$AB$366,$E$10),INDEX('Avalanche Schedule'!$H$7:$H$366,$E$10)-INDEX('Avalanche Schedule'!$AB$7:$AB$366,$E$10))) | D18: =IF(B18="","",IF('Start Here'!$C$7="Snowball",INDEX('Snowball Schedule'!$AB$7:$AB$366,$E$10),INDEX('Avalanche Schedule'!$AB$7:$AB$366,$E$10))) | E18: =IF(B18="","",IF('Start Here'!$C$7="Snowball",'My Debts'!$F$12,'My Debts'!$G$12))
B19: =IF('My Debts'!$B$13="","",'My Debts'!$B$13) | C19: =IF(B19="","",IF('Start Here'!$C$7="Snowball",INDEX('Snowball Schedule'!$I$7:$I$366,$E$10)-INDEX('Snowball Schedule'!$AC$7:$AC$366,$E$10),INDEX('Avalanche Schedule'!$I$7:$I$366,$E$10)-INDEX('Avalanche Schedule'!$AC$7:$AC$366,$E$10))) | D19: =IF(B19="","",IF('Start Here'!$C$7="Snowball",INDEX('Snowball Schedule'!$AC$7:$AC$366,$E$10),INDEX('Avalanche Schedule'!$AC$7:$AC$366,$E$10))) | E19: =IF(B19="","",IF('Start Here'!$C$7="Snowball",'My Debts'!$F$13,'My Debts'!$G$13)) | G19: PAYOFF ORDER (YOUR PLAN)
B20: =IF('My Debts'!$B$14="","",'My Debts'!$B$14) | C20: =IF(B20="","",IF('Start Here'!$C$7="Snowball",INDEX('Snowball Schedule'!$J$7:$J$366,$E$10)-INDEX('Snowball Schedule'!$AD$7:$AD$366,$E$10),INDEX('Avalanche Schedule'!$J$7:$J$366,$E$10)-INDEX('Avalanche Schedule'!$AD$7:$AD$366,$E$10))) | D20: =IF(B20="","",IF('Start Here'!$C$7="Snowball",INDEX('Snowball Schedule'!$AD$7:$AD$366,$E$10),INDEX('Avalanche Schedule'!$AD$7:$AD$366,$E$10))) | E20: =IF(B20="","",IF('Start Here'!$C$7="Snowball",'My Debts'!$F$14,'My Debts'!$G$14)) | G20: # | H20: Debt | I20: Paid off | J20: Interest paid
B21: =IF('My Debts'!$B$15="","",'My Debts'!$B$15) | C21: =IF(B21="","",IF('Start Here'!$C$7="Snowball",INDEX('Snowball Schedule'!$K$7:$K$366,$E$10)-INDEX('Snowball Schedule'!$AE$7:$AE$366,$E$10),INDEX('Avalanche Schedule'!$K$7:$K$366,$E$10)-INDEX('Avalanche Schedule'!$AE$7:$AE$366,$E$10))) | D21: =IF(B21="","",IF('Start Here'!$C$7="Snowball",INDEX('Snowball Schedule'!$AE$7:$AE$366,$E$10),INDEX('Avalanche Schedule'!$AE$7:$AE$366,$E$10))) | E21: =IF(B21="","",IF('Start Here'!$C$7="Snowball",'My Debts'!$F$15,'My Debts'!$G$15)) | G21: =IF(ISNA(MATCH(1,IF('Start Here'!$C$7="Snowball",'My Debts'!$F$6:$F$15,'My Debts'!$G$6:$G$15),0)),"",1) -> 1 | H21: =IF(G21="","",INDEX('My Debts'!$B$6:$B$15,MATCH(1,IF('Start Here'!$C$7="Snowball",'My Debts'!$F$6:$F$15,'My Debts'!$G$6:$G$15),0))) -> Store card (example) | I21: =IF(G21="","",INDEX('My Debts'!$H$6:$H$15,MATCH(1,IF('Start Here'!$C$7="Snowball",'My Debts'!$F$6:$F$15,'My Debts'!$G$6:$G$15),0))) -> 46327 | J21: =IF(G21="","",INDEX('My Debts'!$I$6:$I$15,MATCH(1,IF('Start Here'!$C$7="Snowball",'My Debts'!$F$6:$F$15,'My Debts'!$G$6:$G$15),0))) -> 20.56
B22: Total | C22: =SUM(C12:C21) -> 1200 | D22: =SUM(D12:D21) -> 13804.19 | G22: =IF(ISNA(MATCH(2,IF('Start Here'!$C$7="Snowball",'My Debts'!$F$6:$F$15,'My Debts'!$G$6:$G$15),0)),"",2) -> 2 | H22: =IF(G22="","",INDEX('My Debts'!$B$6:$B$15,MATCH(2,IF('Start Here'!$C$7="Snowball",'My Debts'!$F$6:$F$15,'My Debts'!$G$6:$G$15),0))) -> Visa (example) | I22: =IF(G22="","",INDEX('My Debts'!$H$6:$H$15,MATCH(2,IF('Start Here'!$C$7="Snowball",'My Debts'!$F$6:$F$15,'My Debts'!$G$6:$G$15),0))) -> 46447 | J22: =IF(G22="","",INDEX('My Debts'!$I$6:$I$15,MATCH(2,IF('Start Here'!$C$7="Snowball",'My Debts'!$F$6:$F$15,'My Debts'!$G$6:$G$15),0))) -> 314.6
G23: =IF(ISNA(MATCH(3,IF('Start Here'!$C$7="Snowball",'My Debts'!$F$6:$F$15,'My Debts'!$G$6:$G$15),0)),"",3) -> 3 | H23: =IF(G23="","",INDEX('My Debts'!$B$6:$B$15,MATCH(3,IF('Start Here'!$C$7="Snowball",'My Debts'!$F$6:$F$15,'My Debts'!$G$6:$G$15),0))) -> Car loan (example) | I23: =IF(G23="","",INDEX('My Debts'!$H$6:$H$15,MATCH(3,IF('Start Here'!$C$7="Snowball",'My Debts'!$F$6:$F$15,'My Debts'!$G$6:$G$15),0))) -> 46692 | J23: =IF(G23="","",INDEX('My Debts'!$I$6:$I$15,MATCH(3,IF('Start Here'!$C$7="Snowball",'My Debts'!$F$6:$F$15,'My Debts'!$G$6:$G$15),0))) -> 512.52
G24: =IF(ISNA(MATCH(4,IF('Start Here'!$C$7="Snowball",'My Debts'!$F$6:$F$15,'My Debts'!$G$6:$G$15),0)),"",4) | H24: =IF(G24="","",INDEX('My Debts'!$B$6:$B$15,MATCH(4,IF('Start Here'!$C$7="Snowball",'My Debts'!$F$6:$F$15,'My Debts'!$G$6:$G$15),0))) | I24: =IF(G24="","",INDEX('My Debts'!$H$6:$H$15,MATCH(4,IF('Start Here'!$C$7="Snowball",'My Debts'!$F$6:$F$15,'My Debts'!$G$6:$G$15),0))) | J24: =IF(G24="","",INDEX('My Debts'!$I$6:$I$15,MATCH(4,IF('Start Here'!$C$7="Snowball",'My Debts'!$F$6:$F$15,'My Debts'!$G$6:$G$15),0)))
G25: =IF(ISNA(MATCH(5,IF('Start Here'!$C$7="Snowball",'My Debts'!$F$6:$F$15,'My Debts'!$G$6:$G$15),0)),"",5) | H25: =IF(G25="","",INDEX('My Debts'!$B$6:$B$15,MATCH(5,IF('Start Here'!$C$7="Snowball",'My Debts'!$F$6:$F$15,'My Debts'!$G$6:$G$15),0))) | I25: =IF(G25="","",INDEX('My Debts'!$H$6:$H$15,MATCH(5,IF('Start Here'!$C$7="Snowball",'My Debts'!$F$6:$F$15,'My Debts'!$G$6:$G$15),0))) | J25: =IF(G25="","",INDEX('My Debts'!$I$6:$I$15,MATCH(5,IF('Start Here'!$C$7="Snowball",'My Debts'!$F$6:$F$15,'My Debts'!$G$6:$G$15),0)))
G26: =IF(ISNA(MATCH(6,IF('Start Here'!$C$7="Snowball",'My Debts'!$F$6:$F$15,'My Debts'!$G$6:$G$15),0)),"",6) | H26: =IF(G26="","",INDEX('My Debts'!$B$6:$B$15,MATCH(6,IF('Start Here'!$C$7="Snowball",'My Debts'!$F$6:$F$15,'My Debts'!$G$6:$G$15),0))) | I26: =IF(G26="","",INDEX('My Debts'!$H$6:$H$15,MATCH(6,IF('Start Here'!$C$7="Snowball",'My Debts'!$F$6:$F$15,'My Debts'!$G$6:$G$15),0))) | J26: =IF(G26="","",INDEX('My Debts'!$I$6:$I$15,MATCH(6,IF('Start Here'!$C$7="Snowball",'My Debts'!$F$6:$F$15,'My Debts'!$G$6:$G$15),0)))
G27: =IF(ISNA(MATCH(7,IF('Start Here'!$C$7="Snowball",'My Debts'!$F$6:$F$15,'My Debts'!$G$6:$G$15),0)),"",7) | H27: =IF(G27="","",INDEX('My Debts'!$B$6:$B$15,MATCH(7,IF('Start Here'!$C$7="Snowball",'My Debts'!$F$6:$F$15,'My Debts'!$G$6:$G$15),0))) | I27: =IF(G27="","",INDEX('My Debts'!$H$6:$H$15,MATCH(7,IF('Start Here'!$C$7="Snowball",'My Debts'!$F$6:$F$15,'My Debts'!$G$6:$G$15),0))) | J27: =IF(G27="","",INDEX('My Debts'!$I$6:$I$15,MATCH(7,IF('Start Here'!$C$7="Snowball",'My Debts'!$F$6:$F$15,'My Debts'!$G$6:$G$15),0)))
G28: =IF(ISNA(MATCH(8,IF('Start Here'!$C$7="Snowball",'My Debts'!$F$6:$F$15,'My Debts'!$G$6:$G$15),0)),"",8) | H28: =IF(G28="","",INDEX('My Debts'!$B$6:$B$15,MATCH(8,IF('Start Here'!$C$7="Snowball",'My Debts'!$F$6:$F$15,'My Debts'!$G$6:$G$15),0))) | I28: =IF(G28="","",INDEX('My Debts'!$H$6:$H$15,MATCH(8,IF('Start Here'!$C$7="Snowball",'My Debts'!$F$6:$F$15,'My Debts'!$G$6:$G$15),0))) | J28: =IF(G28="","",INDEX('My Debts'!$I$6:$I$15,MATCH(8,IF('Start Here'!$C$7="Snowball",'My Debts'!$F$6:$F$15,'My Debts'!$G$6:$G$15),0)))
G29: =IF(ISNA(MATCH(9,IF('Start Here'!$C$7="Snowball",'My Debts'!$F$6:$F$15,'My Debts'!$G$6:$G$15),0)),"",9) | H29: =IF(G29="","",INDEX('My Debts'!$B$6:$B$15,MATCH(9,IF('Start Here'!$C$7="Snowball",'My Debts'!$F$6:$F$15,'My Debts'!$G$6:$G$15),0))) | I29: =IF(G29="","",INDEX('My Debts'!$H$6:$H$15,MATCH(9,IF('Start Here'!$C$7="Snowball",'My Debts'!$F$6:$F$15,'My Debts'!$G$6:$G$15),0))) | J29: =IF(G29="","",INDEX('My Debts'!$I$6:$I$15,MATCH(9,IF('Start Here'!$C$7="Snowball",'My Debts'!$F$6:$F$15,'My Debts'!$G$6:$G$15),0)))
G30: =IF(ISNA(MATCH(10,IF('Start Here'!$C$7="Snowball",'My Debts'!$F$6:$F$15,'My Debts'!$G$6:$G$15),0)),"",10) | H30: =IF(G30="","",INDEX('My Debts'!$B$6:$B$15,MATCH(10,IF('Start Here'!$C$7="Snowball",'My Debts'!$F$6:$F$15,'My Debts'!$G$6:$G$15),0))) | I30: =IF(G30="","",INDEX('My Debts'!$H$6:$H$15,MATCH(10,IF('Start Here'!$C$7="Snowball",'My Debts'!$F$6:$F$15,'My Debts'!$G$6:$G$15),0))) | J30: =IF(G30="","",INDEX('My Debts'!$I$6:$I$15,MATCH(10,IF('Start Here'!$C$7="Snowball",'My Debts'!$F$6:$F$15,'My Debts'!$G$6:$G$15),0)))
B33: BALANCE OVER TIME

Sheet My Debts
A1: My Debts
A2: Enter up to 10 debts. Yellow cells are yours; grey cells calculate automatically.
B5: Debt name | C5: Balance ($) | D5: APR | E5: Minimum payment ($) | F5: Snowball order | G5: Avalanche order | H5: Paid off (your plan) | I5: Interest paid (your plan)
B6: Store card (example) | C6: 850 | D6: 0.2699 | E6: 35 | F6: =IF(C6="",99,SUMPRODUCT(--($C$6:$C$15<>""),--($C$6:$C$15<C6))+COUNTIF($C$6:C6,C6)) -> 1 | G6: =IF(C6="",99,SUMPRODUCT(--($C$6:$C$15<>""),--($D$6:$D$15>D6))+COUNTIF($D$6:D6,D6)) -> 1 | H6: =IF(C6="","",IF(IF('Start Here'!$C$7="Snowball",COUNTIF('Snowball Schedule'!$V$7:$V$366,">0.005")+1,COUNTIF('Avalanche Schedule'!$V$7:$V$366,">0.005")+1)>360,"30+ years",DATE(YEAR('Start Here'!$C$6),MONTH('Start Here'!$C$6)+IF('Start Here'!$C$7="Snowball",COUNTIF('Snowball Schedule'!$V$7:$V$366,">0.005")+1,COUNTIF('Avalanche Schedule'!$V$7:$V$366,">0.005")+1)-1,1))) -> 46327 | I6: =IF(C6="","",IF('Start Here'!$C$7="Snowball",SUM('Snowball Schedule'!$B$7:$B$366)-SUM('Snowball Schedule'!$V$6:$V$365),SUM('Avalanche Schedule'!$B$7:$B$366)-SUM('Avalanche Schedule'!$V$6:$V$365))) -> 20.56
B7: Visa (example) | C7: 4200 | D7: 0.2249 | E7: 110 | F7: =IF(C7="",99,SUMPRODUCT(--($C$6:$C$15<>""),--($C$6:$C$15<C7))+COUNTIF($C$6:C7,C7)) -> 2 | G7: =IF(C7="",99,SUMPRODUCT(--($C$6:$C$15<>""),--($D$6:$D$15>D7))+COUNTIF($D$6:D7,D7)) -> 2 | H7: =IF(C7="","",IF(IF('Start Here'!$C$7="Snowball",COUNTIF('Snowball Schedule'!$W$7:$W$366,">0.005")+1,COUNTIF('Avalanche Schedule'!$W$7:$W$366,">0.005")+1)>360,"30+ years",DATE(YEAR('Start Here'!$C$6),MONTH('Start Here'!$C$6)+IF('Start Here'!$C$7="Snowball",COUNTIF('Snowball Schedule'!$W$7:$W$366,">0.005")+1,COUNTIF('Avalanche Schedule'!$W$7:$W$366,">0.005")+1)-1,1))) -> 46447 | I7: =IF(C7="","",IF('Start Here'!$C$7="Snowball",SUM('Snowball Schedule'!$C$7:$C$366)-SUM('Snowball Schedule'!$W$6:$W$365),SUM('Avalanche Schedule'!$C$7:$C$366)-SUM('Avalanche Schedule'!$W$6:$W$365))) -> 314.6
B8: Car loan (example) | C8: 9800 | D8: 0.069 | E8: 285 | F8: =IF(C8="",99,SUMPRODUCT(--($C$6:$C$15<>""),--($C$6:$C$15<C8))+COUNTIF($C$6:C8,C8)) -> 3 | G8: =IF(C8="",99,SUMPRODUCT(--($C$6:$C$15<>""),--($D$6:$D$15>D8))+COUNTIF($D$6:D8,D8)) -> 3 | H8: =IF(C8="","",IF(IF('Start Here'!$C$7="Snowball",COUNTIF('Snowball Schedule'!$X$7:$X$366,">0.005")+1,COUNTIF('Avalanche Schedule'!$X$7:$X$366,">0.005")+1)>360,"30+ years",DATE(YEAR('Start Here'!$C$6),MONTH('Start Here'!$C$6)+IF('Start Here'!$C$7="Snowball",COUNTIF('Snowball Schedule'!$X$7:$X$366,">0.005")+1,COUNTIF('Avalanche Schedule'!$X$7:$X$366,">0.005")+1)-1,1))) -> 46692 | I8: =IF(C8="","",IF('Start Here'!$C$7="Snowball",SUM('Snowball Schedule'!$D$7:$D$366)-SUM('Snowball Schedule'!$X$6:$X$365),SUM('Avalanche Schedule'!$D$7:$D$366)-SUM('Avalanche Schedule'!$X$6:$X$365))) -> 512.52
F9: =IF(C9="",99,SUMPRODUCT(--($C$6:$C$15<>""),--($C$6:$C$15<C9))+COUNTIF($C$6:C9,C9)) -> 99 | G9: =IF(C9="",99,SUMPRODUCT(--($C$6:$C$15<>""),--($D$6:$D$15>D9))+COUNTIF($D$6:D9,D9)) -> 99 | H9: =IF(C9="","",IF(IF('Start Here'!$C$7="Snowball",COUNTIF('Snowball Schedule'!$Y$7:$Y$366,">0.005")+1,COUNTIF('Avalanche Schedule'!$Y$7:$Y$366,">0.005")+1)>360,"30+ years",DATE(YEAR('Start Here'!$C$6),MONTH('Start Here'!$C$6)+IF('Start Here'!$C$7="Snowball",COUNTIF('Snowball Schedule'!$Y$7:$Y$366,">0.005")+1,COUNTIF('Avalanche Schedule'!$Y$7:$Y$366,">0.005")+1)-1,1))) | I9: =IF(C9="","",IF('Start Here'!$C$7="Snowball",SUM('Snowball Schedule'!$E$7:$E$366)-SUM('Snowball Schedule'!$Y$6:$Y$365),SUM('Avalanche Schedule'!$E$7:$E$366)-SUM('Avalanche Schedule'!$Y$6:$Y$365)))
F10: =IF(C10="",99,SUMPRODUCT(--($C$6:$C$15<>""),--($C$6:$C$15<C10))+COUNTIF($C$6:C10,C10)) -> 99 | G10: =IF(C10="",99,SUMPRODUCT(--($C$6:$C$15<>""),--($D$6:$D$15>D10))+COUNTIF($D$6:D10,D10)) -> 99 | H10: =IF(C10="","",IF(IF('Start Here'!$C$7="Snowball",COUNTIF('Snowball Schedule'!$Z$7:$Z$366,">0.005")+1,COUNTIF('Avalanche Schedule'!$Z$7:$Z$366,">0.005")+1)>360,"30+ years",DATE(YEAR('Start Here'!$C$6),MONTH('Start Here'!$C$6)+IF('Start Here'!$C$7="Snowball",COUNTIF('Snowball Schedule'!$Z$7:$Z$366,">0.005")+1,COUNTIF('Avalanche Schedule'!$Z$7:$Z$366,">0.005")+1)-1,1))) | I10: =IF(C10="","",IF('Start Here'!$C$7="Snowball",SUM('Snowball Schedule'!$F$7:$F$366)-SUM('Snowball Schedule'!$Z$6:$Z$365),SUM('Avalanche Schedule'!$F$7:$F$366)-SUM('Avalanche Schedule'!$Z$6:$Z$365)))
F11: =IF(C11="",99,SUMPRODUCT(--($C$6:$C$15<>""),--($C$6:$C$15<C11))+COUNTIF($C$6:C11,C11)) -> 99 | G11: =IF(C11="",99,SUMPRODUCT(--($C$6:$C$15<>""),--($D$6:$D$15>D11))+COUNTIF($D$6:D11,D11)) -> 99 | H11: =IF(C11="","",IF(IF('Start Here'!$C$7="Snowball",COUNTIF('Snowball Schedule'!$AA$7:$AA$366,">0.005")+1,COUNTIF('Avalanche Schedule'!$AA$7:$AA$366,">0.005")+1)>360,"30+ years",DATE(YEAR('Start Here'!$C$6),MONTH('Start Here'!$C$6)+IF('Start Here'!$C$7="Snowball",COUNTIF('Snowball Schedule'!$AA$7:$AA$366,">0.005")+1,COUNTIF('Avalanche Schedule'!$AA$7:$AA$366,">0.005")+1)-1,1))) | I11: =IF(C11="","",IF('Start Here'!$C$7="Snowball",SUM('Snowball Schedule'!$G$7:$G$366)-SUM('Snowball Schedule'!$AA$6:$AA$365),SUM('Avalanche Schedule'!$G$7:$G$366)-SUM('Avalanche Schedule'!$AA$6:$AA$365)))
F12: =IF(C12="",99,SUMPRODUCT(--($C$6:$C$15<>""),--($C$6:$C$15<C12))+COUNTIF($C$6:C12,C12)) -> 99 | G12: =IF(C12="",99,SUMPRODUCT(--($C$6:$C$15<>""),--($D$6:$D$15>D12))+COUNTIF($D$6:D12,D12)) -> 99 | H12: =IF(C12="","",IF(IF('Start Here'!$C$7="Snowball",COUNTIF('Snowball Schedule'!$AB$7:$AB$366,">0.005")+1,COUNTIF('Avalanche Schedule'!$AB$7:$AB$366,">0.005")+1)>360,"30+ years",DATE(YEAR('Start Here'!$C$6),MONTH('Start Here'!$C$6)+IF('Start Here'!$C$7="Snowball",COUNTIF('Snowball Schedule'!$AB$7:$AB$366,">0.005")+1,COUNTIF('Avalanche Schedule'!$AB$7:$AB$366,">0.005")+1)-1,1))) | I12: =IF(C12="","",IF('Start Here'!$C$7="Snowball",SUM('Snowball Schedule'!$H$7:$H$366)-SUM('Snowball Schedule'!$AB$6:$AB$365),SUM('Avalanche Schedule'!$H$7:$H$366)-SUM('Avalanche Schedule'!$AB$6:$AB$365)))
F13: =IF(C13="",99,SUMPRODUCT(--($C$6:$C$15<>""),--($C$6:$C$15<C13))+COUNTIF($C$6:C13,C13)) -> 99 | G13: =IF(C13="",99,SUMPRODUCT(--($C$6:$C$15<>""),--($D$6:$D$15>D13))+COUNTIF($D$6:D13,D13)) -> 99 | H13: =IF(C13="","",IF(IF('Start Here'!$C$7="Snowball",COUNTIF('Snowball Schedule'!$AC$7:$AC$366,">0.005")+1,COUNTIF('Avalanche Schedule'!$AC$7:$AC$366,">0.005")+1)>360,"30+ years",DATE(YEAR('Start Here'!$C$6),MONTH('Start Here'!$C$6)+IF('Start Here'!$C$7="Snowball",COUNTIF('Snowball Schedule'!$AC$7:$AC$366,">0.005")+1,COUNTIF('Avalanche Schedule'!$AC$7:$AC$366,">0.005")+1)-1,1))) | I13: =IF(C13="","",IF('Start Here'!$C$7="Snowball",SUM('Snowball Schedule'!$I$7:$I$366)-SUM('Snowball Schedule'!$AC$6:$AC$365),SUM('Avalanche Schedule'!$I$7:$I$366)-SUM('Avalanche Schedule'!$AC$6:$AC$365)))
F14: =IF(C14="",99,SUMPRODUCT(--($C$6:$C$15<>""),--($C$6:$C$15<C14))+COUNTIF($C$6:C14,C14)) -> 99 | G14: =IF(C14="",99,SUMPRODUCT(--($C$6:$C$15<>""),--($D$6:$D$15>D14))+COUNTIF($D$6:D14,D14)) -> 99 | H14: =IF(C14="","",IF(IF('Start Here'!$C$7="Snowball",COUNTIF('Snowball Schedule'!$AD$7:$AD$366,">0.005")+1,COUNTIF('Avalanche Schedule'!$AD$7:$AD$366,">0.005")+1)>360,"30+ years",DATE(YEAR('Start Here'!$C$6),MONTH('Start Here'!$C$6)+IF('Start Here'!$C$7="Snowball",COUNTIF('Snowball Schedule'!$AD$7:$AD$366,">0.005")+1,COUNTIF('Avalanche Schedule'!$AD$7:$AD$366,">0.005")+1)-1,1))) | I14: =IF(C14="","",IF('Start Here'!$C$7="Snowball",SUM('Snowball Schedule'!$J$7:$J$366)-SUM('Snowball Schedule'!$AD$6:$AD$365),SUM('Avalanche Schedule'!$J$7:$J$366)-SUM('Avalanche Schedule'!$AD$6:$AD$365)))
F15: =IF(C15="",99,SUMPRODUCT(--($C$6:$C$15<>""),--($C$6:$C$15<C15))+COUNTIF($C$6:C15,C15)) -> 99 | G15: =IF(C15="",99,SUMPRODUCT(--($C$6:$C$15<>""),--($D$6:$D$15>D15))+COUNTIF($D$6:D15,D15)) -> 99 | H15: =IF(C15="","",IF(IF('Start Here'!$C$7="Snowball",COUNTIF('Snowball Schedule'!$AE$7:$AE$366,">0.005")+1,COUNTIF('Avalanche Schedule'!$AE$7:$AE$366,">0.005")+1)>360,"30+ years",DATE(YEAR('Start Here'!$C$6),MONTH('Start Here'!$C$6)+IF('Start Here'!$C$7="Snowball",COUNTIF('Snowball Schedule'!$AE$7:$AE$366,">0.005")+1,COUNTIF('Avalanche Schedule'!$AE$7:$AE$366,">0.005")+1)-1,1))) | I15: =IF(C15="","",IF('Start Here'!$C$7="Snowball",SUM('Snowball Schedule'!$K$7:$K$366)-SUM('Snowball Schedule'!$AE$6:$AE$365),SUM('Avalanche Schedule'!$K$7:$K$366)-SUM('Avalanche Schedule'!$AE$6:$AE$365)))
B16: Total | C16: =SUM(C6:C15) -> 14850 | D16: =IF(C16>0,SUMPRODUCT(C6:C15,D6:D15)/C16,0) -> 0.12459226 | E16: =SUM(E6:E15) -> 430
B18: Delete the example rows and enter your own debts. Rows left blank are ignored.

Sheet Snowball Schedule
A1: Snowball Schedule
A2: Month-by-month simulation. No need to edit this tab.
A4: Priority | B4: ='My Debts'!$F$6 -> 1 | C4: ='My Debts'!$F$7 -> 2 | D4: ='My Debts'!$F$8 -> 3 | E4: ='My Debts'!$F$9 -> 99 | F4: ='My Debts'!$F$10 -> 99 | G4: ='My Debts'!$F$11 -> 99 | H4: ='My Debts'!$F$12 -> 99 | I4: ='My Debts'!$F$13 -> 99 | J4: ='My Debts'!$F$14 -> 99 | K4: ='My Debts'!$F$15 -> 99
A5: Month | B5: =IF('My Debts'!$B$6="","Debt 1",'My Debts'!$B$6)&" · Owed" -> Store card (example) · Owed | C5: =IF('My Debts'!$B$7="","Debt 2",'My Debts'!$B$7)&" · Owed" -> Visa (example) · Owed | D5: =IF('My Debts'!$B$8="","Debt 3",'My Debts'!$B$8)&" · Owed" -> Car loan (example) · Owed | E5: =IF('My Debts'!$B$9="","Debt 4",'My Debts'!$B$9)&" · Owed" -> Debt 4 · Owed | F5: =IF('My Debts'!$B$10="","Debt 5",'My Debts'!$B$10)&" · Owed" -> Debt 5 · Owed | G5: =IF('My Debts'!$B$11="","Debt 6",'My Debts'!$B$11)&" · Owed" -> Debt 6 · Owed | H5: =IF('My Debts'!$B$12="","Debt 7",'My Debts'!$B$12)&" · Owed" -> Debt 7 · Owed | I5: =IF('My Debts'!$B$13="","Debt 8",'My Debts'!$B$13)&" · Owed" -> Debt 8 · Owed | J5: =IF('My Debts'!$B$14="","Debt 9",'My Debts'!$B$14)&" · Owed" -> Debt 9 · Owed | K5: =IF('My Debts'!$B$15="","Debt 10",'My Debts'!$B$15)&" · Owed" -> Debt 10 · Owed | L5: =IF('My Debts'!$B$6="","Debt 1",'My Debts'!$B$6)&" · Minimum" -> Store card (example) · Minimum | M5: =IF('My Debts'!$B$7="","Debt 2",'My Debts'!$B$7)&" · Minimum" -> Visa (example) · Minimum | N5: =IF('My Debts'!$B$8="","Debt 3",'My Debts'!$B$8)&" · Minimum" -> Car loan (example) · Minimum | O5: =IF('My Debts'!$B$9="","Debt 4",'My Debts'!$B$9)&" · Minimum" -> Debt 4 · Minimum | P5: =IF('My Debts'!$B$10="","Debt 5",'My Debts'!$B$10)&" · Minimum" -> Debt 5 · Minimum | Q5: =IF('My Debts'!$B$11="","Debt 6",'My Debts'!$B$11)&" · Minimum" -> Debt 6 · Minimum | R5: =IF('My Debts'!$B$12="","Debt 7",'My Debts'!$B$12)&" · Minimum" -> Debt 7 · Minimum | S5: =IF('My Debts'!$B$13="","Debt 8",'My Debts'!$B$13)&" · Minimum" -> Debt 8 · Minimum | T5: =IF('My Debts'!$B$14="","Debt 9",'My Debts'!$B$14)&" · Minimum" -> Debt 9 · Minimum | U5: =IF('My Debts'!$B$15="","Debt 10",'My Debts'!$B$15)&" · Minimum" -> Debt 10 · Minimum | V5: =IF('My Debts'!$B$6="","Debt 1",'My Debts'!$B$6)&" · End balance" -> Store card (example) · End balance | W5: =IF('My Debts'!$B$7="","Debt 2",'My Debts'!$B$7)&" · End balance" -> Visa (example) · End balance | X5: =IF('My Debts'!$B$8="","Debt 3",'My Debts'!$B$8)&" · End balance" -> Car loan (example) · End balance | Y5: =IF('My Debts'!$B$9="","Debt 4",'My Debts'!$B$9)&" · End balance" -> Debt 4 · End balance | Z5: =IF('My Debts'!$B$10="","Debt 5",'My Debts'!$B$10)&" · End balance" -> Debt 5 · End balance | AA5: =IF('My Debts'!$B$11="","Debt 6",'My Debts'!$B$11)&" · End balance" -> Debt 6 · End balance | AB5: =IF('My Debts'!$B$12="","Debt 7",'My Debts'!$B$12)&" · End balance" -> Debt 7 · End balance | AC5: =IF('My Debts'!$B$13="","Debt 8",'My Debts'!$B$13)&" · End balance" -> Debt 8 · End balance | AD5: =IF('My Debts'!$B$14="","Debt 9",'My Debts'!$B$14)&" · End balance" -> Debt 9 · End balance | AE5: =IF('My Debts'!$B$15="","Debt 10",'My Debts'!$B$15)&" · End balance" -> Debt 10 · End balance | AF5: Extra available | AG5: Total balance | AH5: Interest this month
A6: Start | V6: =N('My Debts'!$C$6) -> 850 | W6: =N('My Debts'!$C$7) -> 4200 | X6: =N('My Debts'!$C$8) -> 9800 | Y6: =N('My Debts'!$C$9) -> 0 | Z6: =N('My Debts'!$C$10) -> 0 | AA6: =N('My Debts'!$C$11) -> 0 | AB6: =N('My Debts'!$C$12) -> 0 | AC6: =N('My Debts'!$C$13) -> 0 | AD6: =N('My Debts'!$C$14) -> 0 | AE6: =N('My Debts'!$C$15) -> 0 | AG6: =SUM(V6:AE6) -> 14850
A7: =DATE(YEAR('Start Here'!$C$6),MONTH('Start Here'!$C$6)+0,1) -> 46296 | B7: =ROUND(V6*(1+N('My Debts'!$D$6)/12),2) -> 869.12 | C7: =ROUND(W6*(1+N('My Debts'!$D$7)/12),2) -> 4278.72 | D7: =ROUND(X6*(1+N('My Debts'!$D$8)/12),2) -> 9856.35 | E7: =ROUND(Y6*(1+N('My Debts'!$D$9)/12),2) -> 0 | F7: =ROUND(Z6*(1+N('My Debts'!$D$10)/12),2) -> 0 | G7: =ROUND(AA6*(1+N('My Debts'!$D$11)/12),2) -> 0 | H7: =ROUND(AB6*(1+N('My Debts'!$D$12)/12),2) -> 0 | I7: =ROUND(AC6*(1+N('My Debts'!$D$13)/12),2) -> 0 | J7: =ROUND(AD6*(1+N('My Debts'!$D$14)/12),2) -> 0 | K7: =ROUND(AE6*(1+N('My Debts'!$D$15)/12),2) -> 0 | L7: =MIN(N('My Debts'!$E$6),B7) -> 35 | M7: =MIN(N('My Debts'!$E$7),C7) -> 110 | N7: =MIN(N('My Debts'!$E$8),D7) -> 285 | O7: =MIN(N('My Debts'!$E$9),E7) -> 0 | P7: =MIN(N('My Debts'!$E$10),F7) -> 0 | Q7: =MIN(N('My Debts'!$E$11),G7) -> 0 | R7: =MIN(N('My Debts'!$E$12),H7) -> 0 | S7: =MIN(N('My Debts'!$E$13),I7) -> 0 | T7: =MIN(N('My Debts'!$E$14),J7) -> 0 | U7: =MIN(N('My Debts'!$E$15),K7) -> 0 | V7: =ROUND(B7-L7-MIN(B7-L7,MAX(0,$AF7-SUMPRODUCT(--($B$4:$K$4<B$4),$B7:$K7-$L7:$U7))),2) -> 64.12 | W7: =ROUND(C7-M7-MIN(C7-M7,MAX(0,$AF7-SUMPRODUCT(--($B$4:$K$4<C$4),$B7:$K7-$L7:$U7))),2) -> 4168.72 | X7: =ROUND(D7-N7-MIN(D7-N7,MAX(0,$AF7-SUMPRODUCT(--($B$4:$K$4<D$4),$B7:$K7-$L7:$U7))),2) -> 9571.35 | Y7: =ROUND(E7-O7-MIN(E7-O7,MAX(0,$AF7-SUMPRODUCT(--($B$4:$K$4<E$4),$B7:$K7-$L7:$U7))),2) -> 0 | Z7: =ROUND(F7-P7-MIN(F7-P7,MAX(0,$AF7-SUMPRODUCT(--($B$4:$K$4<F$4),$B7:$K7-$L7:$U7))),2) -> 0 | AA7: =ROUND(G7-Q7-MIN(G7-Q7,MAX(0,$AF7-SUMPRODUCT(--($B$4:$K$4<G$4),$B7:$K7-$L7:$U7))),2) -> 0 | AB7: =ROUND(H7-R7-MIN(H7-R7,MAX(0,$AF7-SUMPRODUCT(--($B$4:$K$4<H$4),$B7:$K7-$L7:$U7))),2) -> 0 | AC7: =ROUND(I7-S7-MIN(I7-S7,MAX(0,$AF7-SUMPRODUCT(--($B$4:$K$4<I$4),$B7:$K7-$L7:$U7))),2) -> 0 | ... AE7: =ROUND(K7-U7-MIN(K7-U7,MAX(0,$AF7-SUMPRODUCT(--($B$4:$K$4<K$4),$B7:$K7-$L7:$U7))),2) -> 0 | AF7: =MAX(0,'Start Here'!$C$5-SUM($L7:$U7)) -> 770 | AG7: =SUM(V7:AE7) -> 13804.19 | AH7: =SUM(B7:K7)-AG6 -> 154.19
A8: =DATE(YEAR('Start Here'!$C$6),MONTH('Start Here'!$C$6)+1,1) -> 46327 | B8: =ROUND(V7*(1+N('My Debts'!$D$6)/12),2) -> 65.56 | C8: =ROUND(W7*(1+N('My Debts'!$D$7)/12),2) -> 4246.85 | D8: =ROUND(X7*(1+N('My Debts'!$D$8)/12),2) -> 9626.39 | E8: =ROUND(Y7*(1+N('My Debts'!$D$9)/12),2) -> 0 | F8: =ROUND(Z7*(1+N('My Debts'!$D$10)/12),2) -> 0 | G8: =ROUND(AA7*(1+N('My Debts'!$D$11)/12),2) -> 0 | H8: =ROUND(AB7*(1+N('My Debts'!$D$12)/12),2) -> 0 | I8: =ROUND(AC7*(1+N('My Debts'!$D$13)/12),2) -> 0 | J8: =ROUND(AD7*(1+N('My Debts'!$D$14)/12),2) -> 0 | K8: =ROUND(AE7*(1+N('My Debts'!$D$15)/12),2) -> 0 | L8: =MIN(N('My Debts'!$E$6),B8) -> 35 | M8: =MIN(N('My Debts'!$E$7),C8) -> 110 | N8: =MIN(N('My Debts'!$E$8),D8) -> 285 | O8: =MIN(N('My Debts'!$E$9),E8) -> 0 | P8: =MIN(N('My Debts'!$E$10),F8) -> 0 | Q8: =MIN(N('My Debts'!$E$11),G8) -> 0 | R8: =MIN(N('My Debts'!$E$12),H8) -> 0 | S8: =MIN(N('My Debts'!$E$13),I8) -> 0 | T8: =MIN(N('My Debts'!$E$14),J8) -> 0 | U8: =MIN(N('My Debts'!$E$15),K8) -> 0 | V8: =ROUND(B8-L8-MIN(B8-L8,MAX(0,$AF8-SUMPRODUCT(--($B$4:$K$4<B$4),$B8:$K8-$L8:$U8))),2) -> 0 | W8: =ROUND(C8-M8-MIN(C8-M8,MAX(0,$AF8-SUMPRODUCT(--($B$4:$K$4<C$4),$B8:$K8-$L8:$U8))),2) -> 3397.41 | X8: =ROUND(D8-N8-MIN(D8-N8,MAX(0,$AF8-SUMPRODUCT(--($B$4:$K$4<D$4),$B8:$K8-$L8:$U8))),2) -> 9341.39 | Y8: =ROUND(E8-O8-MIN(E8-O8,MAX(0,$AF8-SUMPRODUCT(--($B$4:$K$4<E$4),$B8:$K8-$L8:$U8))),2) -> 0 | Z8: =ROUND(F8-P8-MIN(F8-P8,MAX(0,$AF8-SUMPRODUCT(--($B$4:$K$4<F$4),$B8:$K8-$L8:$U8))),2) -> 0 | AA8: =ROUND(G8-Q8-MIN(G8-Q8,MAX(0,$AF8-SUMPRODUCT(--($B$4:$K$4<G$4),$B8:$K8-$L8:$U8))),2) -> 0 | AB8: =ROUND(H8-R8-MIN(H8-R8,MAX(0,$AF8-SUMPRODUCT(--($B$4:$K$4<H$4),$B8:$K8-$L8:$U8))),2) -> 0 | AC8: =ROUND(I8-S8-MIN(I8-S8,MAX(0,$AF8-SUMPRODUCT(--($B$4:$K$4<I$4),$B8:$K8-$L8:$U8))),2) -> 0 | ... AE8: =ROUND(K8-U8-MIN(K8-U8,MAX(0,$AF8-SUMPRODUCT(--($B$4:$K$4<K$4),$B8:$K8-$L8:$U8))),2) -> 0 | AF8: =MAX(0,'Start Here'!$C$5-SUM($L8:$U8)) -> 770 | AG8: =SUM(V8:AE8) -> 12738.8 | AH8: =SUM(B8:K8)-AG7 -> 134.61
A9: =DATE(YEAR('Start Here'!$C$6),MONTH('Start Here'!$C$6)+2,1) -> 46357 | B9: =ROUND(V8*(1+N('My Debts'!$D$6)/12),2) -> 0 | C9: =ROUND(W8*(1+N('My Debts'!$D$7)/12),2) -> 3461.08 | D9: =ROUND(X8*(1+N('My Debts'!$D$8)/12),2) -> 9395.1 | E9: =ROUND(Y8*(1+N('My Debts'!$D$9)/12),2) -> 0 | F9: =ROUND(Z8*(1+N('My Debts'!$D$10)/12),2) -> 0 | G9: =ROUND(AA8*(1+N('My Debts'!$D$11)/12),2) -> 0 | H9: =ROUND(AB8*(1+N('My Debts'!$D$12)/12),2) -> 0 | I9: =ROUND(AC8*(1+N('My Debts'!$D$13)/12),2) -> 0 | J9: =ROUND(AD8*(1+N('My Debts'!$D$14)/12),2) -> 0 | K9: =ROUND(AE8*(1+N('My Debts'!$D$15)/12),2) -> 0 | L9: =MIN(N('My Debts'!$E$6),B9) -> 0 | M9: =MIN(N('My Debts'!$E$7),C9) -> 110 | N9: =MIN(N('My Debts'!$E$8),D9) -> 285 | O9: =MIN(N('My Debts'!$E$9),E9) -> 0 | P9: =MIN(N('My Debts'!$E$10),F9) -> 0 | Q9: =MIN(N('My Debts'!$E$11),G9) -> 0 | R9: =MIN(N('My Debts'!$E$12),H9) -> 0 | S9: =MIN(N('My Debts'!$E$13),I9) -> 0 | T9: =MIN(N('My Debts'!$E$14),J9) -> 0 | U9: =MIN(N('My Debts'!$E$15),K9) -> 0 | V9: =ROUND(B9-L9-MIN(B9-L9,MAX(0,$AF9-SUMPRODUCT(--($B$4:$K$4<B$4),$B9:$K9-$L9:$U9))),2) -> 0 | W9: =ROUND(C9-M9-MIN(C9-M9,MAX(0,$AF9-SUMPRODUCT(--($B$4:$K$4<C$4),$B9:$K9-$L9:$U9))),2) -> 2546.08 | X9: =ROUND(D9-N9-MIN(D9-N9,MAX(0,$AF9-SUMPRODUCT(--($B$4:$K$4<D$4),$B9:$K9-$L9:$U9))),2) -> 9110.1 | Y9: =ROUND(E9-O9-MIN(E9-O9,MAX(0,$AF9-SUMPRODUCT(--($B$4:$K$4<E$4),$B9:$K9-$L9:$U9))),2) -> 0 | Z9: =ROUND(F9-P9-MIN(F9-P9,MAX(0,$AF9-SUMPRODUCT(--($B$4:$K$4<F$4),$B9:$K9-$L9:$U9))),2) -> 0 | AA9: =ROUND(G9-Q9-MIN(G9-Q9,MAX(0,$AF9-SUMPRODUCT(--($B$4:$K$4<G$4),$B9:$K9-$L9:$U9))),2) -> 0 | AB9: =ROUND(H9-R9-MIN(H9-R9,MAX(0,$AF9-SUMPRODUCT(--($B$4:$K$4<H$4),$B9:$K9-$L9:$U9))),2) -> 0 | AC9: =ROUND(I9-S9-MIN(I9-S9,MAX(0,$AF9-SUMPRODUCT(--($B$4:$K$4<I$4),$B9:$K9-$L9:$U9))),2) -> 0 | ... AE9: =ROUND(K9-U9-MIN(K9-U9,MAX(0,$AF9-SUMPRODUCT(--($B$4:$K$4<K$4),$B9:$K9-$L9:$U9))),2) -> 0 | AF9: =MAX(0,'Start Here'!$C$5-SUM($L9:$U9)) -> 805 | AG9: =SUM(V9:AE9) -> 11656.18 | AH9: =SUM(B9:K9)-AG8 -> 117.38
A10: =DATE(YEAR('Start Here'!$C$6),MONTH('Start Here'!$C$6)+3,1) -> 46388 | B10: =ROUND(V9*(1+N('My Debts'!$D$6)/12),2) -> 0 | C10: =ROUND(W9*(1+N('My Debts'!$D$7)/12),2) -> 2593.8 | D10: =ROUND(X9*(1+N('My Debts'!$D$8)/12),2) -> 9162.48 | E10: =ROUND(Y9*(1+N('My Debts'!$D$9)/12),2) -> 0 | F10: =ROUND(Z9*(1+N('My Debts'!$D$10)/12),2) -> 0 | G10: =ROUND(AA9*(1+N('My Debts'!$D$11)/12),2) -> 0 | H10: =ROUND(AB9*(1+N('My Debts'!$D$12)/12),2) -> 0 | I10: =ROUND(AC9*(1+N('My Debts'!$D$13)/12),2) -> 0 | J10: =ROUND(AD9*(1+N('My Debts'!$D$14)/12),2) -> 0 | K10: =ROUND(AE9*(1+N('My Debts'!$D$15)/12),2) -> 0 | L10: =MIN(N('My Debts'!$E$6),B10) -> 0 | M10: =MIN(N('My Debts'!$E$7),C10) -> 110 | N10: =MIN(N('My Debts'!$E$8),D10) -> 285 | O10: =MIN(N('My Debts'!$E$9),E10) -> 0 | P10: =MIN(N('My Debts'!$E$10),F10) -> 0 | Q10: =MIN(N('My Debts'!$E$11),G10) -> 0 | R10: =MIN(N('My Debts'!$E$12),H10) -> 0 | S10: =MIN(N('My Debts'!$E$13),I10) -> 0 | T10: =MIN(N('My Debts'!$E$14),J10) -> 0 | U10: =MIN(N('My Debts'!$E$15),K10) -> 0 | V10: =ROUND(B10-L10-MIN(B10-L10,MAX(0,$AF10-SUMPRODUCT(--($B$4:$K$4<B$4),$B10:$K10-$L10:$U10))),2) -> 0 | W10: =ROUND(C10-M10-MIN(C10-M10,MAX(0,$AF10-SUMPRODUCT(--($B$4:$K$4<C$4),$B10:$K10-$L10:$U10))),2) -> 1678.8 | X10: =ROUND(D10-N10-MIN(D10-N10,MAX(0,$AF10-SUMPRODUCT(--($B$4:$K$4<D$4),$B10:$K10-$L10:$U10))),2) -> 8877.48 | Y10: =ROUND(E10-O10-MIN(E10-O10,MAX(0,$AF10-SUMPRODUCT(--($B$4:$K$4<E$4),$B10:$K10-$L10:$U10))),2) -> 0 | Z10: =ROUND(F10-P10-MIN(F10-P10,MAX(0,$AF10-SUMPRODUCT(--($B$4:$K$4<F$4),$B10:$K10-$L10:$U10))),2) -> 0 | AA10: =ROUND(G10-Q10-MIN(G10-Q10,MAX(0,$AF10-SUMPRODUCT(--($B$4:$K$4<G$4),$B10:$K10-$L10:$U10))),2) -> 0 | AB10: =ROUND(H10-R10-MIN(H10-R10,MAX(0,$AF10-SUMPRODUCT(--($B$4:$K$4<H$4),$B10:$K10-$L10:$U10))),2) -> 0 | AC10: =ROUND(I10-S10-MIN(I10-S10,MAX(0,$AF10-SUMPRODUCT(--($B$4:$K$4<I$4),$B10:$K10-$L10:$U10))),2) -> 0 | ... AE10: =ROUND(K10-U10-MIN(K10-U10,MAX(0,$AF10-SUMPRODUCT(--($B$4:$K$4<K$4),$B10:$K10-$L10:$U10))),2) -> 0 | AF10: =MAX(0,'Start Here'!$C$5-SUM($L10:$U10)) -> 805 | AG10: =SUM(V10:AE10) -> 10556.28 | AH10: =SUM(B10:K10)-AG9 -> 100.1
A11: =DATE(YEAR('Start Here'!$C$6),MONTH('Start Here'!$C$6)+4,1) -> 46419 | B11: =ROUND(V10*(1+N('My Debts'!$D$6)/12),2) -> 0 | C11: =ROUND(W10*(1+N('My Debts'!$D$7)/12),2) -> 1710.26 | D11: =ROUND(X10*(1+N('My Debts'!$D$8)/12),2) -> 8928.53 | E11: =ROUND(Y10*(1+N('My Debts'!$D$9)/12),2) -> 0 | F11: =ROUND(Z10*(1+N('My Debts'!$D$10)/12),2) -> 0 | G11: =ROUND(AA10*(1+N('My Debts'!$D$11)/12),2) -> 0 | H11: =ROUND(AB10*(1+N('My Debts'!$D$12)/12),2) -> 0 | I11: =ROUND(AC10*(1+N('My Debts'!$D$13)/12),2) -> 0 | J11: =ROUND(AD10*(1+N('My Debts'!$D$14)/12),2) -> 0 | K11: =ROUND(AE10*(1+N('My Debts'!$D$15)/12),2) -> 0 | L11: =MIN(N('My Debts'!$E$6),B11) -> 0 | M11: =MIN(N('My Debts'!$E$7),C11) -> 110 | N11: =MIN(N('My Debts'!$E$8),D11) -> 285 | O11: =MIN(N('My Debts'!$E$9),E11) -> 0 | P11: =MIN(N('My Debts'!$E$10),F11) -> 0 | Q11: =MIN(N('My Debts'!$E$11),G11) -> 0 | R11: =MIN(N('My Debts'!$E$12),H11) -> 0 | S11: =MIN(N('My Debts'!$E$13),I11) -> 0 | T11: =MIN(N('My Debts'!$E$14),J11) -> 0 | U11: =MIN(N('My Debts'!$E$15),K11) -> 0 | V11: =ROUND(B11-L11-MIN(B11-L11,MAX(0,$AF11-SUMPRODUCT(--($B$4:$K$4<B$4),$B11:$K11-$L11:$U11))),2) -> 0 | W11: =ROUND(C11-M11-MIN(C11-M11,MAX(0,$AF11-SUMPRODUCT(--($B$4:$K$4<C$4),$B11:$K11-$L11:$U11))),2) -> 795.26 | X11: =ROUND(D11-N11-MIN(D11-N11,MAX(0,$AF11-SUMPRODUCT(--($B$4:$K$4<D$4),$B11:$K11-$L11:$U11))),2) -> 8643.53 | Y11: =ROUND(E11-O11-MIN(E11-O11,MAX(0,$AF11-SUMPRODUCT(--($B$4:$K$4<E$4),$B11:$K11-$L11:$U11))),2) -> 0 | Z11: =ROUND(F11-P11-MIN(F11-P11,MAX(0,$AF11-SUMPRODUCT(--($B$4:$K$4<F$4),$B11:$K11-$L11:$U11))),2) -> 0 | AA11: =ROUND(G11-Q11-MIN(G11-Q11,MAX(0,$AF11-SUMPRODUCT(--($B$4:$K$4<G$4),$B11:$K11-$L11:$U11))),2) -> 0 | AB11: =ROUND(H11-R11-MIN(H11-R11,MAX(0,$AF11-SUMPRODUCT(--($B$4:$K$4<H$4),$B11:$K11-$L11:$U11))),2) -> 0 | AC11: =ROUND(I11-S11-MIN(I11-S11,MAX(0,$AF11-SUMPRODUCT(--($B$4:$K$4<I$4),$B11:$K11-$L11:$U11))),2) -> 0 | ... AE11: =ROUND(K11-U11-MIN(K11-U11,MAX(0,$AF11-SUMPRODUCT(--($B$4:$K$4<K$4),$B11:$K11-$L11:$U11))),2) -> 0 | AF11: =MAX(0,'Start Here'!$C$5-SUM($L11:$U11)) -> 805 | AG11: =SUM(V11:AE11) -> 9438.79 | AH11: =SUM(B11:K11)-AG10 -> 82.51
A12: =DATE(YEAR('Start Here'!$C$6),MONTH('Start Here'!$C$6)+5,1) -> 46447 | B12: =ROUND(V11*(1+N('My Debts'!$D$6)/12),2) -> 0 | C12: =ROUND(W11*(1+N('My Debts'!$D$7)/12),2) -> 810.16 | D12: =ROUND(X11*(1+N('My Debts'!$D$8)/12),2) -> 8693.23 | E12: =ROUND(Y11*(1+N('My Debts'!$D$9)/12),2) -> 0 | F12: =ROUND(Z11*(1+N('My Debts'!$D$10)/12),2) -> 0 | G12: =ROUND(AA11*(1+N('My Debts'!$D$11)/12),2) -> 0 | H12: =ROUND(AB11*(1+N('My Debts'!$D$12)/12),2) -> 0 | I12: =ROUND(AC11*(1+N('My Debts'!$D$13)/12),2) -> 0 | J12: =ROUND(AD11*(1+N('My Debts'!$D$14)/12),2) -> 0 | K12: =ROUND(AE11*(1+N('My Debts'!$D$15)/12),2) -> 0 | L12: =MIN(N('My Debts'!$E$6),B12) -> 0 | M12: =MIN(N('My Debts'!$E$7),C12) -> 110 | N12: =MIN(N('My Debts'!$E$8),D12) -> 285 | O12: =MIN(N('My Debts'!$E$9),E12) -> 0 | P12: =MIN(N('My Debts'!$E$10),F12) -> 0 | Q12: =MIN(N('My Debts'!$E$11),G12) -> 0 | R12: =MIN(N('My Debts'!$E$12),H12) -> 0 | S12: =MIN(N('My Debts'!$E$13),I12) -> 0 | T12: =MIN(N('My Debts'!$E$14),J12) -> 0 | U12: =MIN(N('My Debts'!$E$15),K12) -> 0 | V12: =ROUND(B12-L12-MIN(B12-L12,MAX(0,$AF12-SUMPRODUCT(--($B$4:$K$4<B$4),$B12:$K12-$L12:$U12))),2) -> 0 | W12: =ROUND(C12-M12-MIN(C12-M12,MAX(0,$AF12-SUMPRODUCT(--($B$4:$K$4<C$4),$B12:$K12-$L12:$U12))),2) -> 0 | X12: =ROUND(D12-N12-MIN(D12-N12,MAX(0,$AF12-SUMPRODUCT(--($B$4:$K$4<D$4),$B12:$K12-$L12:$U12))),2) -> 8303.39 | Y12: =ROUND(E12-O12-MIN(E12-O12,MAX(0,$AF12-SUMPRODUCT(--($B$4:$K$4<E$4),$B12:$K12-$L12:$U12))),2) -> 0 | Z12: =ROUND(F12-P12-MIN(F12-P12,MAX(0,$AF12-SUMPRODUCT(--($B$4:$K$4<F$4),$B12:$K12-$L12:$U12))),2) -> 0 | AA12: =ROUND(G12-Q12-MIN(G12-Q12,MAX(0,$AF12-SUMPRODUCT(--($B$4:$K$4<G$4),$B12:$K12-$L12:$U12))),2) -> 0 | AB12: =ROUND(H12-R12-MIN(H12-R12,MAX(0,$AF12-SUMPRODUCT(--($B$4:$K$4<H$4),$B12:$K12-$L12:$U12))),2) -> 0 | AC12: =ROUND(I12-S12-MIN(I12-S12,MAX(0,$AF12-SUMPRODUCT(--($B$4:$K$4<I$4),$B12:$K12-$L12:$U12))),2) -> 0 | ... AE12: =ROUND(K12-U12-MIN(K12-U12,MAX(0,$AF12-SUMPRODUCT(--($B$4:$K$4<K$4),$B12:$K12-$L12:$U12))),2) -> 0 | AF12: =MAX(0,'Start Here'!$C$5-SUM($L12:$U12)) -> 805 | AG12: =SUM(V12:AE12) -> 8303.39 | AH12: =SUM(B12:K12)-AG11 -> 64.6
A13: =DATE(YEAR('Start Here'!$C$6),MONTH('Start Here'!$C$6)+6,1) -> 46478 | B13: =ROUND(V12*(1+N('My Debts'!$D$6)/12),2) -> 0 | C13: =ROUND(W12*(1+N('My Debts'!$D$7)/12),2) -> 0 | D13: =ROUND(X12*(1+N('My Debts'!$D$8)/12),2) -> 8351.13 | E13: =ROUND(Y12*(1+N('My Debts'!$D$9)/12),2) -> 0 | F13: =ROUND(Z12*(1+N('My Debts'!$D$10)/12),2) -> 0 | G13: =ROUND(AA12*(1+N('My Debts'!$D$11)/12),2) -> 0 | H13: =ROUND(AB12*(1+N('My Debts'!$D$12)/12),2) -> 0 | I13: =ROUND(AC12*(1+N('My Debts'!$D$13)/12),2) -> 0 | J13: =ROUND(AD12*(1+N('My Debts'!$D$14)/12),2) -> 0 | K13: =ROUND(AE12*(1+N('My Debts'!$D$15)/12),2) -> 0 | L13: =MIN(N('My Debts'!$E$6),B13) -> 0 | M13: =MIN(N('My Debts'!$E$7),C13) -> 0 | N13: =MIN(N('My Debts'!$E$8),D13) -> 285 | O13: =MIN(N('My Debts'!$E$9),E13) -> 0 | P13: =MIN(N('My Debts'!$E$10),F13) -> 0 | Q13: =MIN(N('My Debts'!$E$11),G13) -> 0 | R13: =MIN(N('My Debts'!$E$12),H13) -> 0 | S13: =MIN(N('My Debts'!$E$13),I13) -> 0 | T13: =MIN(N('My Debts'!$E$14),J13) -> 0 | U13: =MIN(N('My Debts'!$E$15),K13) -> 0 | V13: =ROUND(B13-L13-MIN(B13-L13,MAX(0,$AF13-SUMPRODUCT(--($B$4:$K$4<B$4),$B13:$K13-$L13:$U13))),2) -> 0 | W13: =ROUND(C13-M13-MIN(C13-M13,MAX(0,$AF13-SUMPRODUCT(--($B$4:$K$4<C$4),$B13:$K13-$L13:$U13))),2) -> 0 | X13: =ROUND(D13-N13-MIN(D13-N13,MAX(0,$AF13-SUMPRODUCT(--($B$4:$K$4<D$4),$B13:$K13-$L13:$U13))),2) -> 7151.13 | Y13: =ROUND(E13-O13-MIN(E13-O13,MAX(0,$AF13-SUMPRODUCT(--($B$4:$K$4<E$4),$B13:$K13-$L13:$U13))),2) -> 0 | Z13: =ROUND(F13-P13-MIN(F13-P13,MAX(0,$AF13-SUMPRODUCT(--($B$4:$K$4<F$4),$B13:$K13-$L13:$U13))),2) -> 0 | AA13: =ROUND(G13-Q13-MIN(G13-Q13,MAX(0,$AF13-SUMPRODUCT(--($B$4:$K$4<G$4),$B13:$K13-$L13:$U13))),2) -> 0 | AB13: =ROUND(H13-R13-MIN(H13-R13,MAX(0,$AF13-SUMPRODUCT(--($B$4:$K$4<H$4),$B13:$K13-$L13:$U13))),2) -> 0 | AC13: =ROUND(I13-S13-MIN(I13-S13,MAX(0,$AF13-SUMPRODUCT(--($B$4:$K$4<I$4),$B13:$K13-$L13:$U13))),2) -> 0 | ... AE13: =ROUND(K13-U13-MIN(K13-U13,MAX(0,$AF13-SUMPRODUCT(--($B$4:$K$4<K$4),$B13:$K13-$L13:$U13))),2) -> 0 | AF13: =MAX(0,'Start Here'!$C$5-SUM($L13:$U13)) -> 915 | AG13: =SUM(V13:AE13) -> 7151.13 | AH13: =SUM(B13:K13)-AG12 -> 47.74
A14: =DATE(YEAR('Start Here'!$C$6),MONTH('Start Here'!$C$6)+7,1) -> 46508 | B14: =ROUND(V13*(1+N('My Debts'!$D$6)/12),2) -> 0 | C14: =ROUND(W13*(1+N('My Debts'!$D$7)/12),2) -> 0 | D14: =ROUND(X13*(1+N('My Debts'!$D$8)/12),2) -> 7192.25 | E14: =ROUND(Y13*(1+N('My Debts'!$D$9)/12),2) -> 0 | F14: =ROUND(Z13*(1+N('My Debts'!$D$10)/12),2) -> 0 | G14: =ROUND(AA13*(1+N('My Debts'!$D$11)/12),2) -> 0 | H14: =ROUND(AB13*(1+N('My Debts'!$D$12)/12),2) -> 0 | I14: =ROUND(AC13*(1+N('My Debts'!$D$13)/12),2) -> 0 | J14: =ROUND(AD13*(1+N('My Debts'!$D$14)/12),2) -> 0 | K14: =ROUND(AE13*(1+N('My Debts'!$D$15)/12),2) -> 0 | L14: =MIN(N('My Debts'!$E$6),B14) -> 0 | M14: =MIN(N('My Debts'!$E$7),C14) -> 0 | N14: =MIN(N('My Debts'!$E$8),D14) -> 285 | O14: =MIN(N('My Debts'!$E$9),E14) -> 0 | P14: =MIN(N('My Debts'!$E$10),F14) -> 0 | Q14: =MIN(N('My Debts'!$E$11),G14) -> 0 | R14: =MIN(N('My Debts'!$E$12),H14) -> 0 | S14: =MIN(N('My Debts'!$E$13),I14) -> 0 | T14: =MIN(N('My Debts'!$E$14),J14) -> 0 | U14: =MIN(N('My Debts'!$E$15),K14) -> 0 | V14: =ROUND(B14-L14-MIN(B14-L14,MAX(0,$AF14-SUMPRODUCT(--($B$4:$K$4<B$4),$B14:$K14-$L14:$U14))),2) -> 0 | W14: =ROUND(C14-M14-MIN(C14-M14,MAX(0,$AF14-SUMPRODUCT(--($B$4:$K$4<C$4),$B14:$K14-$L14:$U14))),2) -> 0 | X14: =ROUND(D14-N14-MIN(D14-N14,MAX(0,$AF14-SUMPRODUCT(--($B$4:$K$4<D$4),$B14:$K14-$L14:$U14))),2) -> 5992.25 | Y14: =ROUND(E14-O14-MIN(E14-O14,MAX(0,$AF14-SUMPRODUCT(--($B$4:$K$4<E$4),$B14:$K14-$L14:$U14))),2) -> 0 | Z14: =ROUND(F14-P14-MIN(F14-P14,MAX(0,$AF14-SUMPRODUCT(--($B$4:$K$4<F$4),$B14:$K14-$L14:$U14))),2) -> 0 | AA14: =ROUND(G14-Q14-MIN(G14-Q14,MAX(0,$AF14-SUMPRODUCT(--($B$4:$K$4<G$4),$B14:$K14-$L14:$U14))),2) -> 0 | AB14: =ROUND(H14-R14-MIN(H14-R14,MAX(0,$AF14-SUMPRODUCT(--($B$4:$K$4<H$4),$B14:$K14-$L14:$U14))),2) -> 0 | AC14: =ROUND(I14-S14-MIN(I14-S14,MAX(0,$AF14-SUMPRODUCT(--($B$4:$K$4<I$4),$B14:$K14-$L14:$U14))),2) -> 0 | ... AE14: =ROUND(K14-U14-MIN(K14-U14,MAX(0,$AF14-SUMPRODUCT(--($B$4:$K$4<K$4),$B14:$K14-$L14:$U14))),2) -> 0 | AF14: =MAX(0,'Start Here'!$C$5-SUM($L14:$U14)) -> 915 | AG14: =SUM(V14:AE14) -> 5992.25 | AH14: =SUM(B14:K14)-AG13 -> 41.12
A15: =DATE(YEAR('Start Here'!$C$6),MONTH('Start Here'!$C$6)+8,1) -> 46539 | B15: =ROUND(V14*(1+N('My Debts'!$D$6)/12),2) -> 0 | C15: =ROUND(W14*(1+N('My Debts'!$D$7)/12),2) -> 0 | D15: =ROUND(X14*(1+N('My Debts'!$D$8)/12),2) -> 6026.71 | E15: =ROUND(Y14*(1+N('My Debts'!$D$9)/12),2) -> 0 | F15: =ROUND(Z14*(1+N('My Debts'!$D$10)/12),2) -> 0 | G15: =ROUND(AA14*(1+N('My Debts'!$D$11)/12),2) -> 0 | H15: =ROUND(AB14*(1+N('My Debts'!$D$12)/12),2) -> 0 | I15: =ROUND(AC14*(1+N('My Debts'!$D$13)/12),2) -> 0 | J15: =ROUND(AD14*(1+N('My Debts'!$D$14)/12),2) -> 0 | K15: =ROUND(AE14*(1+N('My Debts'!$D$15)/12),2) -> 0 | L15: =MIN(N('My Debts'!$E$6),B15) -> 0 | M15: =MIN(N('My Debts'!$E$7),C15) -> 0 | N15: =MIN(N('My Debts'!$E$8),D15) -> 285 | O15: =MIN(N('My Debts'!$E$9),E15) -> 0 | P15: =MIN(N('My Debts'!$E$10),F15) -> 0 | Q15: =MIN(N('My Debts'!$E$11),G15) -> 0 | R15: =MIN(N('My Debts'!$E$12),H15) -> 0 | S15: =MIN(N('My Debts'!$E$13),I15) -> 0 | T15: =MIN(N('My Debts'!$E$14),J15) -> 0 | U15: =MIN(N('My Debts'!$E$15),K15) -> 0 | V15: =ROUND(B15-L15-MIN(B15-L15,MAX(0,$AF15-SUMPRODUCT(--($B$4:$K$4<B$4),$B15:$K15-$L15:$U15))),2) -> 0 | W15: =ROUND(C15-M15-MIN(C15-M15,MAX(0,$AF15-SUMPRODUCT(--($B$4:$K$4<C$4),$B15:$K15-$L15:$U15))),2) -> 0 | X15: =ROUND(D15-N15-MIN(D15-N15,MAX(0,$AF15-SUMPRODUCT(--($B$4:$K$4<D$4),$B15:$K15-$L15:$U15))),2) -> 4826.71 | Y15: =ROUND(E15-O15-MIN(E15-O15,MAX(0,$AF15-SUMPRODUCT(--($B$4:$K$4<E$4),$B15:$K15-$L15:$U15))),2) -> 0 | Z15: =ROUND(F15-P15-MIN(F15-P15,MAX(0,$AF15-SUMPRODUCT(--($B$4:$K$4<F$4),$B15:$K15-$L15:$U15))),2) -> 0 | AA15: =ROUND(G15-Q15-MIN(G15-Q15,MAX(0,$AF15-SUMPRODUCT(--($B$4:$K$4<G$4),$B15:$K15-$L15:$U15))),2) -> 0 | AB15: =ROUND(H15-R15-MIN(H15-R15,MAX(0,$AF15-SUMPRODUCT(--($B$4:$K$4<H$4),$B15:$K15-$L15:$U15))),2) -> 0 | AC15: =ROUND(I15-S15-MIN(I15-S15,MAX(0,$AF15-SUMPRODUCT(--($B$4:$K$4<I$4),$B15:$K15-$L15:$U15))),2) -> 0 | ... AE15: =ROUND(K15-U15-MIN(K15-U15,MAX(0,$AF15-SUMPRODUCT(--($B$4:$K$4<K$4),$B15:$K15-$L15:$U15))),2) -> 0 | AF15: =MAX(0,'Start Here'!$C$5-SUM($L15:$U15)) -> 915 | AG15: =SUM(V15:AE15) -> 4826.71 | AH15: =SUM(B15:K15)-AG14 -> 34.46
A16: =DATE(YEAR('Start Here'!$C$6),MONTH('Start Here'!$C$6)+9,1) -> 46569 | B16: =ROUND(V15*(1+N('My Debts'!$D$6)/12),2) -> 0 | C16: =ROUND(W15*(1+N('My Debts'!$D$7)/12),2) -> 0 | D16: =ROUND(X15*(1+N('My Debts'!$D$8)/12),2) -> 4854.46 | E16: =ROUND(Y15*(1+N('My Debts'!$D$9)/12),2) -> 0 | F16: =ROUND(Z15*(1+N('My Debts'!$D$10)/12),2) -> 0 | G16: =ROUND(AA15*(1+N('My Debts'!$D$11)/12),2) -> 0 | H16: =ROUND(AB15*(1+N('My Debts'!$D$12)/12),2) -> 0 | I16: =ROUND(AC15*(1+N('My Debts'!$D$13)/12),2) -> 0 | J16: =ROUND(AD15*(1+N('My Debts'!$D$14)/12),2) -> 0 | K16: =ROUND(AE15*(1+N('My Debts'!$D$15)/12),2) -> 0 | L16: =MIN(N('My Debts'!$E$6),B16) -> 0 | M16: =MIN(N('My Debts'!$E$7),C16) -> 0 | N16: =MIN(N('My Debts'!$E$8),D16) -> 285 | O16: =MIN(N('My Debts'!$E$9),E16) -> 0 | P16: =MIN(N('My Debts'!$E$10),F16) -> 0 | Q16: =MIN(N('My Debts'!$E$11),G16) -> 0 | R16: =MIN(N('My Debts'!$E$12),H16) -> 0 | S16: =MIN(N('My Debts'!$E$13),I16) -> 0 | T16: =MIN(N('My Debts'!$E$14),J16) -> 0 | U16: =MIN(N('My Debts'!$E$15),K16) -> 0 | V16: =ROUND(B16-L16-MIN(B16-L16,MAX(0,$AF16-SUMPRODUCT(--($B$4:$K$4<B$4),$B16:$K16-$L16:$U16))),2) -> 0 | W16: =ROUND(C16-M16-MIN(C16-M16,MAX(0,$AF16-SUMPRODUCT(--($B$4:$K$4<C$4),$B16:$K16-$L16:$U16))),2) -> 0 | X16: =ROUND(D16-N16-MIN(D16-N16,MAX(0,$AF16-SUMPRODUCT(--($B$4:$K$4<D$4),$B16:$K16-$L16:$U16))),2) -> 3654.46 | Y16: =ROUND(E16-O16-MIN(E16-O16,MAX(0,$AF16-SUMPRODUCT(--($B$4:$K$4<E$4),$B16:$K16-$L16:$U16))),2) -> 0 | Z16: =ROUND(F16-P16-MIN(F16-P16,MAX(0,$AF16-SUMPRODUCT(--($B$4:$K$4<F$4),$B16:$K16-$L16:$U16))),2) -> 0 | AA16: =ROUND(G16-Q16-MIN(G16-Q16,MAX(0,$AF16-SUMPRODUCT(--($B$4:$K$4<G$4),$B16:$K16-$L16:$U16))),2) -> 0 | AB16: =ROUND(H16-R16-MIN(H16-R16,MAX(0,$AF16-SUMPRODUCT(--($B$4:$K$4<H$4),$B16:$K16-$L16:$U16))),2) -> 0 | AC16: =ROUND(I16-S16-MIN(I16-S16,MAX(0,$AF16-SUMPRODUCT(--($B$4:$K$4<I$4),$B16:$K16-$L16:$U16))),2) -> 0 | ... AE16: =ROUND(K16-U16-MIN(K16-U16,MAX(0,$AF16-SUMPRODUCT(--($B$4:$K$4<K$4),$B16:$K16-$L16:$U16))),2) -> 0 | AF16: =MAX(0,'Start Here'!$C$5-SUM($L16:$U16)) -> 915 | AG16: =SUM(V16:AE16) -> 3654.46 | AH16: =SUM(B16:K16)-AG15 -> 27.75
A17: =DATE(YEAR('Start Here'!$C$6),MONTH('Start Here'!$C$6)+10,1) -> 46600 | B17: =ROUND(V16*(1+N('My Debts'!$D$6)/12),2) -> 0 | C17: =ROUND(W16*(1+N('My Debts'!$D$7)/12),2) -> 0 | D17: =ROUND(X16*(1+N('My Debts'!$D$8)/12),2) -> 3675.47 | E17: =ROUND(Y16*(1+N('My Debts'!$D$9)/12),2) -> 0 | F17: =ROUND(Z16*(1+N('My Debts'!$D$10)/12),2) -> 0 | G17: =ROUND(AA16*(1+N('My Debts'!$D$11)/12),2) -> 0 | H17: =ROUND(AB16*(1+N('My Debts'!$D$12)/12),2) -> 0 | I17: =ROUND(AC16*(1+N('My Debts'!$D$13)/12),2) -> 0 | J17: =ROUND(AD16*(1+N('My Debts'!$D$14)/12),2) -> 0 | K17: =ROUND(AE16*(1+N('My Debts'!$D$15)/12),2) -> 0 | L17: =MIN(N('My Debts'!$E$6),B17) -> 0 | M17: =MIN(N('My Debts'!$E$7),C17) -> 0 | N17: =MIN(N('My Debts'!$E$8),D17) -> 285 | O17: =MIN(N('My Debts'!$E$9),E17) -> 0 | P17: =MIN(N('My Debts'!$E$10),F17) -> 0 | Q17: =MIN(N('My Debts'!$E$11),G17) -> 0 | R17: =MIN(N('My Debts'!$E$12),H17) -> 0 | S17: =MIN(N('My Debts'!$E$13),I17) -> 0 | T17: =MIN(N('My Debts'!$E$14),J17) -> 0 | U17: =MIN(N('My Debts'!$E$15),K17) -> 0 | V17: =ROUND(B17-L17-MIN(B17-L17,MAX(0,$AF17-SUMPRODUCT(--($B$4:$K$4<B$4),$B17:$K17-$L17:$U17))),2) -> 0 | W17: =ROUND(C17-M17-MIN(C17-M17,MAX(0,$AF17-SUMPRODUCT(--($B$4:$K$4<C$4),$B17:$K17-$L17:$U17))),2) -> 0 | X17: =ROUND(D17-N17-MIN(D17-N17,MAX(0,$AF17-SUMPRODUCT(--($B$4:$K$4<D$4),$B17:$K17-$L17:$U17))),2) -> 2475.47 | Y17: =ROUND(E17-O17-MIN(E17-O17,MAX(0,$AF17-SUMPRODUCT(--($B$4:$K$4<E$4),$B17:$K17-$L17:$U17))),2) -> 0 | Z17: =ROUND(F17-P17-MIN(F17-P17,MAX(0,$AF17-SUMPRODUCT(--($B$4:$K$4<F$4),$B17:$K17-$L17:$U17))),2) -> 0 | AA17: =ROUND(G17-Q17-MIN(G17-Q17,MAX(0,$AF17-SUMPRODUCT(--($B$4:$K$4<G$4),$B17:$K17-$L17:$U17))),2) -> 0 | AB17: =ROUND(H17-R17-MIN(H17-R17,MAX(0,$AF17-SUMPRODUCT(--($B$4:$K$4<H$4),$B17:$K17-$L17:$U17))),2) -> 0 | AC17: =ROUND(I17-S17-MIN(I17-S17,MAX(0,$AF17-SUMPRODUCT(--($B$4:$K$4<I$4),$B17:$K17-$L17:$U17))),2) -> 0 | ... AE17: =ROUND(K17-U17-MIN(K17-U17,MAX(0,$AF17-SUMPRODUCT(--($B$4:$K$4<K$4),$B17:$K17-$L17:$U17))),2) -> 0 | AF17: =MAX(0,'Start Here'!$C$5-SUM($L17:$U17)) -> 915 | AG17: =SUM(V17:AE17) -> 2475.47 | AH17: =SUM(B17:K17)-AG16 -> 21.01
A18: =DATE(YEAR('Start Here'!$C$6),MONTH('Start Here'!$C$6)+11,1) -> 46631 | B18: =ROUND(V17*(1+N('My Debts'!$D$6)/12),2) -> 0 | C18: =ROUND(W17*(1+N('My Debts'!$D$7)/12),2) -> 0 | D18: =ROUND(X17*(1+N('My Debts'!$D$8)/12),2) -> 2489.7 | E18: =ROUND(Y17*(1+N('My Debts'!$D$9)/12),2) -> 0 | F18: =ROUND(Z17*(1+N('My Debts'!$D$10)/12),2) -> 0 | G18: =ROUND(AA17*(1+N('My Debts'!$D$11)/12),2) -> 0 | H18: =ROUND(AB17*(1+N('My Debts'!$D$12)/12),2) -> 0 | I18: =ROUND(AC17*(1+N('My Debts'!$D$13)/12),2) -> 0 | J18: =ROUND(AD17*(1+N('My Debts'!$D$14)/12),2) -> 0 | K18: =ROUND(AE17*(1+N('My Debts'!$D$15)/12),2) -> 0 | L18: =MIN(N('My Debts'!$E$6),B18) -> 0 | M18: =MIN(N('My Debts'!$E$7),C18) -> 0 | N18: =MIN(N('My Debts'!$E$8),D18) -> 285 | O18: =MIN(N('My Debts'!$E$9),E18) -> 0 | P18: =MIN(N('My Debts'!$E$10),F18) -> 0 | Q18: =MIN(N('My Debts'!$E$11),G18) -> 0 | R18: =MIN(N('My Debts'!$E$12),H18) -> 0 | S18: =MIN(N('My Debts'!$E$13),I18) -> 0 | T18: =MIN(N('My Debts'!$E$14),J18) -> 0 | U18: =MIN(N('My Debts'!$E$15),K18) -> 0 | V18: =ROUND(B18-L18-MIN(B18-L18,MAX(0,$AF18-SUMPRODUCT(--($B$4:$K$4<B$4),$B18:$K18-$L18:$U18))),2) -> 0 | W18: =ROUND(C18-M18-MIN(C18-M18,MAX(0,$AF18-SUMPRODUCT(--($B$4:$K$4<C$4),$B18:$K18-$L18:$U18))),2) -> 0 | X18: =ROUND(D18-N18-MIN(D18-N18,MAX(0,$AF18-SUMPRODUCT(--($B$4:$K$4<D$4),$B18:$K18-$L18:$U18))),2) -> 1289.7 | Y18: =ROUND(E18-O18-MIN(E18-O18,MAX(0,$AF18-SUMPRODUCT(--($B$4:$K$4<E$4),$B18:$K18-$L18:$U18))),2) -> 0 | Z18: =ROUND(F18-P18-MIN(F18-P18,MAX(0,$AF18-SUMPRODUCT(--($B$4:$K$4<F$4),$B18:$K18-$L18:$U18))),2) -> 0 | AA18: =ROUND(G18-Q18-MIN(G18-Q18,MAX(0,$AF18-SUMPRODUCT(--($B$4:$K$4<G$4),$B18:$K18-$L18:$U18))),2) -> 0 | AB18: =ROUND(H18-R18-MIN(H18-R18,MAX(0,$AF18-SUMPRODUCT(--($B$4:$K$4<H$4),$B18:$K18-$L18:$U18))),2) -> 0 | AC18: =ROUND(I18-S18-MIN(I18-S18,MAX(0,$AF18-SUMPRODUCT(--($B$4:$K$4<I$4),$B18:$K18-$L18:$U18))),2) -> 0 | ... AE18: =ROUND(K18-U18-MIN(K18-U18,MAX(0,$AF18-SUMPRODUCT(--($B$4:$K$4<K$4),$B18:$K18-$L18:$U18))),2) -> 0 | AF18: =MAX(0,'Start Here'!$C$5-SUM($L18:$U18)) -> 915 | AG18: =SUM(V18:AE18) -> 1289.7 | AH18: =SUM(B18:K18)-AG17 -> 14.23
A19: =DATE(YEAR('Start Here'!$C$6),MONTH('Start Here'!$C$6)+12,1) -> 46661 | B19: =ROUND(V18*(1+N('My Debts'!$D$6)/12),2) -> 0 | C19: =ROUND(W18*(1+N('My Debts'!$D$7)/12),2) -> 0 | D19: =ROUND(X18*(1+N('My Debts'!$D$8)/12),2) -> 1297.12 | E19: =ROUND(Y18*(1+N('My Debts'!$D$9)/12),2) -> 0 | F19: =ROUND(Z18*(1+N('My Debts'!$D$10)/12),2) -> 0 | G19: =ROUND(AA18*(1+N('My Debts'!$D$11)/12),2) -> 0 | H19: =ROUND(AB18*(1+N('My Debts'!$D$12)/12),2) -> 0 | I19: =ROUND(AC18*(1+N('My Debts'!$D$13)/12),2) -> 0 | J19: =ROUND(AD18*(1+N('My Debts'!$D$14)/12),2) -> 0 | K19: =ROUND(AE18*(1+N('My Debts'!$D$15)/12),2) -> 0 | L19: =MIN(N('My Debts'!$E$6),B19) -> 0 | M19: =MIN(N('My Debts'!$E$7),C19) -> 0 | N19: =MIN(N('My Debts'!$E$8),D19) -> 285 | O19: =MIN(N('My Debts'!$E$9),E19) -> 0 | P19: =MIN(N('My Debts'!$E$10),F19) -> 0 | Q19: =MIN(N('My Debts'!$E$11),G19) -> 0 | R19: =MIN(N('My Debts'!$E$12),H19) -> 0 | S19: =MIN(N('My Debts'!$E$13),I19) -> 0 | T19: =MIN(N('My Debts'!$E$14),J19) -> 0 | U19: =MIN(N('My Debts'!$E$15),K19) -> 0 | V19: =ROUND(B19-L19-MIN(B19-L19,MAX(0,$AF19-SUMPRODUCT(--($B$4:$K$4<B$4),$B19:$K19-$L19:$U19))),2) -> 0 | W19: =ROUND(C19-M19-MIN(C19-M19,MAX(0,$AF19-SUMPRODUCT(--($B$4:$K$4<C$4),$B19:$K19-$L19:$U19))),2) -> 0 | X19: =ROUND(D19-N19-MIN(D19-N19,MAX(0,$AF19-SUMPRODUCT(--($B$4:$K$4<D$4),$B19:$K19-$L19:$U19))),2) -> 97.12 | Y19: =ROUND(E19-O19-MIN(E19-O19,MAX(0,$AF19-SUMPRODUCT(--($B$4:$K$4<E$4),$B19:$K19-$L19:$U19))),2) -> 0 | Z19: =ROUND(F19-P19-MIN(F19-P19,MAX(0,$AF19-SUMPRODUCT(--($B$4:$K$4<F$4),$B19:$K19-$L19:$U19))),2) -> 0 | AA19: =ROUND(G19-Q19-MIN(G19-Q19,MAX(0,$AF19-SUMPRODUCT(--($B$4:$K$4<G$4),$B19:$K19-$L19:$U19))),2) -> 0 | AB19: =ROUND(H19-R19-MIN(H19-R19,MAX(0,$AF19-SUMPRODUCT(--($B$4:$K$4<H$4),$B19:$K19-$L19:$U19))),2) -> 0 | AC19: =ROUND(I19-S19-MIN(I19-S19,MAX(0,$AF19-SUMPRODUCT(--($B$4:$K$4<I$4),$B19:$K19-$L19:$U19))),2) -> 0 | ... AE19: =ROUND(K19-U19-MIN(K19-U19,MAX(0,$AF19-SUMPRODUCT(--($B$4:$K$4<K$4),$B19:$K19-$L19:$U19))),2) -> 0 | AF19: =MAX(0,'Start Here'!$C$5-SUM($L19:$U19)) -> 915 | AG19: =SUM(V19:AE19) -> 97.12 | AH19: =SUM(B19:K19)-AG18 -> 7.42
A20: =DATE(YEAR('Start Here'!$C$6),MONTH('Start Here'!$C$6)+13,1) -> 46692 | B20: =ROUND(V19*(1+N('My Debts'!$D$6)/12),2) -> 0 | C20: =ROUND(W19*(1+N('My Debts'!$D$7)/12),2) -> 0 | D20: =ROUND(X19*(1+N('My Debts'!$D$8)/12),2) -> 97.68 | E20: =ROUND(Y19*(1+N('My Debts'!$D$9)/12),2) -> 0 | F20: =ROUND(Z19*(1+N('My Debts'!$D$10)/12),2) -> 0 | G20: =ROUND(AA19*(1+N('My Debts'!$D$11)/12),2) -> 0 | H20: =ROUND(AB19*(1+N('My Debts'!$D$12)/12),2) -> 0 | I20: =ROUND(AC19*(1+N('My Debts'!$D$13)/12),2) -> 0 | J20: =ROUND(AD19*(1+N('My Debts'!$D$14)/12),2) -> 0 | K20: =ROUND(AE19*(1+N('My Debts'!$D$15)/12),2) -> 0 | L20: =MIN(N('My Debts'!$E$6),B20) -> 0 | M20: =MIN(N('My Debts'!$E$7),C20) -> 0 | N20: =MIN(N('My Debts'!$E$8),D20) -> 97.68 | O20: =MIN(N('My Debts'!$E$9),E20) -> 0 | P20: =MIN(N('My Debts'!$E$10),F20) -> 0 | Q20: =MIN(N('My Debts'!$E$11),G20) -> 0 | R20: =MIN(N('My Debts'!$E$12),H20) -> 0 | S20: =MIN(N('My Debts'!$E$13),I20) -> 0 | T20: =MIN(N('My Debts'!$E$14),J20) -> 0 | U20: =MIN(N('My Debts'!$E$15),K20) -> 0 | V20: =ROUND(B20-L20-MIN(B20-L20,MAX(0,$AF20-SUMPRODUCT(--($B$4:$K$4<B$4),$B20:$K20-$L20:$U20))),2) -> 0 | W20: =ROUND(C20-M20-MIN(C20-M20,MAX(0,$AF20-SUMPRODUCT(--($B$4:$K$4<C$4),$B20:$K20-$L20:$U20))),2) -> 0 | X20: =ROUND(D20-N20-MIN(D20-N20,MAX(0,$AF20-SUMPRODUCT(--($B$4:$K$4<D$4),$B20:$K20-$L20:$U20))),2) -> 0 | Y20: =ROUND(E20-O20-MIN(E20-O20,MAX(0,$AF20-SUMPRODUCT(--($B$4:$K$4<E$4),$B20:$K20-$L20:$U20))),2) -> 0 | Z20: =ROUND(F20-P20-MIN(F20-P20,MAX(0,$AF20-SUMPRODUCT(--($B$4:$K$4<F$4),$B20:$K20-$L20:$U20))),2) -> 0 | AA20: =ROUND(G20-Q20-MIN(G20-Q20,MAX(0,$AF20-SUMPRODUCT(--($B$4:$K$4<G$4),$B20:$K20-$L20:$U20))),2) -> 0 | AB20: =ROUND(H20-R20-MIN(H20-R20,MAX(0,$AF20-SUMPRODUCT(--($B$4:$K$4<H$4),$B20:$K20-$L20:$U20))),2) -> 0 | AC20: =ROUND(I20-S20-MIN(I20-S20,MAX(0,$AF20-SUMPRODUCT(--($B$4:$K$4<I$4),$B20:$K20-$L20:$U20))),2) -> 0 | ... AE20: =ROUND(K20-U20-MIN(K20-U20,MAX(0,$AF20-SUMPRODUCT(--($B$4:$K$4<K$4),$B20:$K20-$L20:$U20))),2) -> 0 | AF20: =MAX(0,'Start Here'!$C$5-SUM($L20:$U20)) -> 1102.32 | AG20: =SUM(V20:AE20) -> 0 | AH20: =SUM(B20:K20)-AG19 -> 0.56
A21: =DATE(YEAR('Start Here'!$C$6),MONTH('Start Here'!$C$6)+14,1) -> 46722 | B21: =ROUND(V20*(1+N('My Debts'!$D$6)/12),2) -> 0 | C21: =ROUND(W20*(1+N('My Debts'!$D$7)/12),2) -> 0 | D21: =ROUND(X20*(1+N('My Debts'!$D$8)/12),2) -> 0 | E21: =ROUND(Y20*(1+N('My Debts'!$D$9)/12),2) -> 0 | F21: =ROUND(Z20*(1+N('My Debts'!$D$10)/12),2) -> 0 | G21: =ROUND(AA20*(1+N('My Debts'!$D$11)/12),2) -> 0 | H21: =ROUND(AB20*(1+N('My Debts'!$D$12)/12),2) -> 0 | I21: =ROUND(AC20*(1+N('My Debts'!$D$13)/12),2) -> 0 | J21: =ROUND(AD20*(1+N('My Debts'!$D$14)/12),2) -> 0 | K21: =ROUND(AE20*(1+N('My Debts'!$D$15)/12),2) -> 0 | L21: =MIN(N('My Debts'!$E$6),B21) -> 0 | M21: =MIN(N('My Debts'!$E$7),C21) -> 0 | N21: =MIN(N('My Debts'!$E$8),D21) -> 0 | O21: =MIN(N('My Debts'!$E$9),E21) -> 0 | P21: =MIN(N('My Debts'!$E$10),F21) -> 0 | Q21: =MIN(N('My Debts'!$E$11),G21) -> 0 | R21: =MIN(N('My Debts'!$E$12),H21) -> 0 | S21: =MIN(N('My Debts'!$E$13),I21) -> 0 | T21: =MIN(N('My Debts'!$E$14),J21) -> 0 | U21: =MIN(N('My Debts'!$E$15),K21) -> 0 | V21: =ROUND(B21-L21-MIN(B21-L21,MAX(0,$AF21-SUMPRODUCT(--($B$4:$K$4<B$4),$B21:$K21-$L21:$U21))),2) -> 0 | W21: =ROUND(C21-M21-MIN(C21-M21,MAX(0,$AF21-SUMPRODUCT(--($B$4:$K$4<C$4),$B21:$K21-$L21:$U21))),2) -> 0 | X21: =ROUND(D21-N21-MIN(D21-N21,MAX(0,$AF21-SUMPRODUCT(--($B$4:$K$4<D$4),$B21:$K21-$L21:$U21))),2) -> 0 | Y21: =ROUND(E21-O21-MIN(E21-O21,MAX(0,$AF21-SUMPRODUCT(--($B$4:$K$4<E$4),$B21:$K21-$L21:$U21))),2) -> 0 | Z21: =ROUND(F21-P21-MIN(F21-P21,MAX(0,$AF21-SUMPRODUCT(--($B$4:$K$4<F$4),$B21:$K21-$L21:$U21))),2) -> 0 | AA21: =ROUND(G21-Q21-MIN(G21-Q21,MAX(0,$AF21-SUMPRODUCT(--($B$4:$K$4<G$4),$B21:$K21-$L21:$U21))),2) -> 0 | AB21: =ROUND(H21-R21-MIN(H21-R21,MAX(0,$AF21-SUMPRODUCT(--($B$4:$K$4<H$4),$B21:$K21-$L21:$U21))),2) -> 0 | AC21: =ROUND(I21-S21-MIN(I21-S21,MAX(0,$AF21-SUMPRODUCT(--($B$4:$K$4<I$4),$B21:$K21-$L21:$U21))),2) -> 0 | ... AE21: =ROUND(K21-U21-MIN(K21-U21,MAX(0,$AF21-SUMPRODUCT(--($B$4:$K$4<K$4),$B21:$K21-$L21:$U21))),2) -> 0 | AF21: =MAX(0,'Start Here'!$C$5-SUM($L21:$U21)) -> 1200 | AG21: =SUM(V21:AE21) -> 0 | AH21: =SUM(B21:K21)-AG20 -> 0
